Workbook

Sheet INDEX
B2: EmpID
B3: Name
B4: Title
B5: Business Unit
B6: Grade
B7: Manager
B8: Location
B9: Role/Exp
B10: Function
B11: Compensation
B12: Comp Trend 2022
B13: Comp Trend 2023
B14: Comp Trend 2024
A15: TALENT PROFILE | B15: TR Rating
B16: TR Trend 2022
B17: TR Trend 2023
B18: TR Trend 2024
B19: Ability
B20: Aspiration
B21: Alignment
B22: Perf 24-25 (H1)
B23: Perf 24-25 (H2)
B24: Perf 25-26 (H1)
B25: Risk of Loss
B26: Impact of Loss
B27: Willing to Relocate
A28: LEADERSHIP IMPACT | B28: 360 Assessment
B29: 360 Trend 2022
B30: 360 Trend 2023
B31: 360 Trend 2024
B32: Manager Climate
B33: Climate Trend 2022
B34: Climate Trend 2023
B35: Climate Trend 2024
B36: GPTW Score
B37: GPTW Trend 2022
B38: GPTW Trend 2023
B39: GPTW Trend 2024

Sheet Profile
A1: EmpID | B1: Name | C1: Title | D1: Business Unit | E1: Grade | F1: Manager | G1: Location | H1: Exp in Current Role | I1: Exp in Current Org | J1: Exp in Current Org (Overall Exp) | K1: Current Experience | L1: Previous Experience | M1: Function | N1: Compensation FY 26-27 | O1: Comp Trend FY 25-26 | P1: Comp Trend FY 24-25 | Q1: Total Unvested LTIP Benefit | R1: Last Promotion Date | S1: TR Rating FY 25-26 | T1: TR Trend FY 24-25 | U1: TR Trend FY 23-24 | V1: Ability | W1: Aspiration | X1: Alignment | Y1: Perf 25-26 (H1) | Z1: Perf 24-25 (H2) | AA1: Perf 24-25 (H1) | AB1: Risk of Loss | AC1: Impact of Loss | AD1: Willing to Relocate | AE1: 360 Trend 2025 | AF1: 360 Trend 2023 | AG1: 360 Trend 2024 | AH1: Manager Climate Score FY26-27 | AI1: Manager Climate Score FY24-25 | AJ1: Manager Climate Score FY25-26 | AK1: GPTW Score 2025 | AL1: GPTW Score 2024 | AM1: GPTW Score 2023
A2: 35000745 | B2: Sundeep Kumar | C2: Chief Manager - Projects | D2: Sterlite Electric | E2: M4 | F2: Sharma, Manoj | G2: Project Site - HR | I2: 7 | J2: 23.2 | K2: Chief Business Officer - Overhead & MSI (2021-Present) , Vice President Projects (2019-2021) | L2: Punj Lloyd Limited (2008-2019), Bharat Heavy Electricals Limited (2002-2007), Honda Motorcycle & Scooter India Pvt. Ltd. (2002 – 2002) | M2: Projects Execution | R2: 43719 | S2: 5 | T2: 5 | U2: - | Y2: 80 | Z2: 88 | AA2: 100 | AB2: Medium | AC2: Medium | AD2: No | AE2: - | AH2: 82 | AI2: 90 | AJ2: 89 | AK2: - | AL2: -
A3: 35000172 | B3: Prapin Samanta | C3: Assistant Vice President - Projects | D3: Sterlite Electric | E3: M3 | F3: Tripathi, Avadhesh | G3: Project Site - WB | I3: 7 | J3: 23.2 | K3: CFO- SEL (2026- Present) | L3: Tenneco Clean Air India Limited (2024-2026), Azure Power India Pvt Ltd (2023-2024), Sterlite Power Transmission Ltd ( 2019-20223) | M3: Projects Execution | S3: 5 | T3: 5 | U3: 5 | Y3: 105 | Z3: - | AA3: - | AB3: Medium | AC3: Medium | AD3: Yes | AE3: - | AH3: 78 | AI3: 67 | AJ3: 91 | AK3: - | AL3: -
A4: 35000985 | B4: Aashif Alam | C4: Chief Manager- Projects (Wind) | D4: Serentica | E4: M4 | F4: Chakraborty, Amit Kumar | G4: Project Site - MH | I4: 7 | J4: 23.2 | K4: Head- Strategy & M&A (2026-Present), VP - Strategy & Finance, MD Office (2024-2026) | L4: Suminter India Organic (2023-2024), Bajaj Electricals Ltd (2019-2023), Voltas Ltd (2016-2019) | M4: Projects Execution | S4: 5 | T4: 5 | U4: - | Y4: 120 | Z4: 110 | AA4: 100 | AB4: Medium | AC4: Medium | AD4: Yes | AE4: - | AH4: 66 | AI4: 88 | AJ4: 82 | AK4: 84 | AL4: -
A5: 35001312 | B5: Prashant Sinha | C5: CEO - Resonia | D5: Resonia | E5: M1A | F5: Agarwal, Pratik | G5: Mumbai - BKC | I5: 1.8 | J5: 12 | K5: Head - Manufacturing Operations (2026-Present), Vice President - Manufacturing Operations (2024-2026) | L5: Indoasian Legrand Group (1999-2024) | M5: Projects Execution | R5: 43565 | S5: 8 | T5: 8 | U5: - | Y5: 90 | Z5: 95 | AA5: - | AB5: Low | AC5: High | AD5: No | AE5: 4.27 | AH5: 89 | AI5: 89 | AJ5: 90 | AK5: 89 | AL5: -
A6: 35001546 | B6: Harish kumar | C6: Chief Manager- Projects (Wind) | D6: Serentica | E6: M4A | F6: J, Balakrishnan | G6: Project Site - KA | I6: 3.8 | J6: 14 | K6: Head- Strategy & M&A (2026-Present), VP - Strategy & Finance, MD Office (2024-2026) | L6: Suminter India Organic (2023-2024), Bajaj Electricals Ltd (2019-2023), Voltas Ltd (2016-2019) | M6: Projects Execution | R6: 44119 | S6: 5 | T6: - | U6: - | Y6: 95 | Z6: 98 | AA6: 100 | AB6: Medium | AC6: Medium | AD6: Yes | AE6: - | AH6: - | AI6: - | AJ6: - | AK6: - | AL6: -
A7: 24900238 | B7: Prashant Saha | C7: Chief Manager - Production | D7: Sterlite Electric | E7: M4A | F7: Chowdhury, Ratul | G7: Rakholi Plant - DNH | I7: 0 | J7: 19.7 | K7: CFO- SEL (2026- Present) | L7: Tenneco Clean Air India Limited (2024-2026), Azure Power India Pvt Ltd (2023-2024), Sterlite Power Transmission Ltd ( 2019-20223) | M7: Manufacturing | S7: 5 | T7: 5 | U7: 5 | Y7: 80 | Z7: 88 | AA7: 100 | AB7: Medium | AC7: Medium | AD7: No | AE7: - | AH7: 82 | AI7: 90 | AJ7: 89 | AK7: - | AL7: -
A8: 35001906 | B8: Suraj Parkash | C8: Chief Manager - Production | D8: Sterlite Electric | E8: M4 | F8: Kumar, Santosh | G8: Jharsuguda Plant - OR | I8: 2.2 | J8: 29.5 | K8: Head - Manufacturing Operations (2026-Present), Vice President - Manufacturing Operations (2024-2026) | L8: Indoasian Legrand Group (1999-2024) | M8: Manufacturing | S8: 5 | T8: - | U8: - | Y8: 105 | Z8: 102 | AA8: 110 | AB8: High | AC8: High | AD8: No | AE8: - | AH8: 78 | AI8: 67 | AJ8: 91 | AK8: - | AL8: -
A9: 35001762 | B9: Ankit Agrawal | C9: Chief Manager - S&OP | D9: Sterlite Electric | E9: M4 | F9: Mattoo, Surinder | G9: Gurugram Office | I9: 1.8 | J9: 12 | K9: Head- Strategy & M&A (2026-Present), VP - Strategy & Finance, MD Office (2024-2026) | L9: Suminter India Organic (2023-2024), Bajaj Electricals Ltd (2019-2023), Voltas Ltd (2016-2019) | M9: Sales | S9: 5 | T9: - | U9: - | Y9: 120 | Z9: 110 | AA9: 100 | AB9: Low | AC9: Low | AD9: Yes | AE9: - | AH9: 66 | AI9: 88 | AJ9: 82 | AK9: - | AL9: -
A10: 24903846 | B10: Amey Sukhthanker | C10: Vice President- Sales and Alliance | D10: Sterlite Electric | E10: M2 | F10: Deshraj, Surya Rajshekhar | G10: Mumbai - Vikhroli | I10: 3.8 | J10: 14 | K10: Chief Business Officer - Overhead & MSI (2021-Present) , Vice President Projects (2019-2021) | L10: Punj Lloyd Limited (2008-2019), Bharat Heavy Electricals Limited (2002-2007), Honda Motorcycle & Scooter India Pvt. Ltd. (2002 – 2002) | M10: Convergence | S10: 6 | T10: 6 | U10: 5 | Y10: 90 | Z10: 95 | AA10: 99 | AB10: High | AC10: High | AD10: No | AE10: - | AH10: 89 | AI10: 89 | AJ10: 90 | AK10: - | AL10: -
A11: 35001657 | B11: Deepak Jaiswal | C11: Chief Manager - Billing and Collections | D11: Sterlite Electric | E11: M4 | F11: Sukhthanker, Amey | G11: Gurugram Office | I11: 7 | J11: 23.2 | K11: CFO- SEL (2026- Present) | L11: Tenneco Clean Air India Limited (2024-2026), Azure Power India Pvt Ltd (2023-2024), Sterlite Power Transmission Ltd ( 2019-20223) | M11: Convergence | S11: 5 | T11: - | U11: - | Y11: 95 | Z11: 98 | AA11: 100 | AB11: Low | AC11: Medium | AD11: Yes | AE11: - | AH11: - | AI11: - | AJ11: - | AK11: - | AL11: -
A12: 24900651 | B12: Nishant Tyagi | C12: Chief Manager - Manufacturing | D12: Sterlite Electric | E12: M4A | F12: Bhati, Himanshu | G12: Haridwar Plant - UKH | I12: 0 | J12: 19.7 | K12: Head - Manufacturing Operations (2026-Present), Vice President - Manufacturing Operations (2024-2026) | L12: Indoasian Legrand Group (1999-2024) | M12: Manufacturing | S12: 6 | T12: 6 | U12: 5 | Y12: 80 | Z12: 88 | AA12: 100 | AB12: High | AC12: High | AD12: Yes | AE12: - | AH12: - | AI12: - | AJ12: - | AK12: - | AL12: -
A13: 24901511 | B13: Hemsingh Hansawat | C13: Chief Manager - Customer Support Organization | D13: Sterlite Electric | E13: M4 | F13: Kapoor, Lokesh | G13: Haridwar Plant - UKH | I13: 2.2 | J13: 29.5 | K13: Head- Strategy & M&A (2026-Present), VP - Strategy & Finance, MD Office (2024-2026) | L13: Suminter India Organic (2023-2024), Bajaj Electricals Ltd (2019-2023), Voltas Ltd (2016-2019) | M13: Sales | S13: 3 | T13: 5 | U13: - | Y13: 105 | Z13: 102 | AA13: 110 | AB13: Low | AC13: Medium | AD13: Yes | AE13: - | AH13: - | AI13: - | AJ13: - | AK13: - | AL13: -
A14: 24901832 | B14: Kishore Amitraj | C14: Assistant Vice President - Claims & Contracts | D14: Sterlite Electric | E14: M3 | F14: Bhardwaj, Ankit | G14: Gurugram Office | I14: 1.8 | J14: 12 | K14: Chief Business Officer - Overhead & MSI (2021-Present) , Vice President Projects (2019-2021) | L14: Punj Lloyd Limited (2008-2019), Bharat Heavy Electricals Limited (2002-2007), Honda Motorcycle & Scooter India Pvt. Ltd. (2002 – 2002) | M14: Projects Execution | S14: 5 | T14: 5 | U14: 5 | Y14: 120 | Z14: - | AA14: - | AB14: Medium | AC14: High | AD14: No | AE14: - | AH14: - | AI14: - | AJ14: - | AK14: - | AL14: -
A15: 24903159 | B15: Kamal Khanna | C15: Assistant Vice President - Product Development | D15: Sterlite Electric | E15: M3 | F15: Mattoo, Surinder | G15: Gurugram Office | I15: 3.8 | J15: 14 | K15: CFO- SEL (2026- Present) | L15: Tenneco Clean Air India Limited (2024-2026), Azure Power India Pvt Ltd (2023-2024), Sterlite Power Transmission Ltd ( 2019-20223) | M15: Plant NPD | S15: 6 | T15: 5 | U15: 6 | Y15: - | Z15: - | AA15: - | AB15: Medium | AC15: High | AD15: Yes | AE15: - | AH15: 78 | AI15: 79 | AJ15: 80 | AK15: - | AL15: -
A16: 35001576 | B16: Divya Vyas | C16: Chief Manager - Cable Exports | D16: Sterlite Electric | E16: M4 | F16: Gupta, Vibhor | G16: Gurugram Office | I16: 7 | J16: 23.2 | K16: Head - Manufacturing Operations (2026-Present), Vice President - Manufacturing Operations (2024-2026) | L16: Indoasian Legrand Group (1999-2024) | M16: Sales | S16: 5 | T16: - | U16: - | Y16: 95 | Z16: - | AA16: 100 | AB16: Medium | AC16: High | AD16: Yes | AE16: - | AH16: 89 | AI16: 90 | AJ16: 88 | AK16: - | AL16: -
A17: 35001891 | B17: Abdul Samad jailaani | C17: Chief Manager - Manufacturing | D17: Sterlite Electric | E17: M4A | F17: Jaiswal, Rahul | G17: Vadodara Plant – GJ | I17: 0 | J17: 19.7 | K17: Head- Strategy & M&A (2026-Present), VP - Strategy & Finance, MD Office (2024-2026) | L17: Suminter India Organic (2023-2024), Bajaj Electricals Ltd (2019-2023), Voltas Ltd (2016-2019) | M17: Manufacturing | S17: 5 | T17: - | U17: - | Y17: 80 | Z17: 88 | AA17: 100 | AB17: Low | AC17: High | AD17: Yes | AE17: - | AH17: 82 | AI17: 90 | AJ17: 89 | AK17: - | AL17: -
A18: 24903188 | B18: Arpit Shrivastava | C18: Chief Manager - Service Delivery | D18: Sterlite Electric | E18: M4 | F18: Dangat, Nilesh | G18: Mumbai - Vikhroli | I18: 2.2 | J18: 29.5 | K18: Chief Business Officer - Overhead & MSI (2021-Present) , Vice President Projects (2019-2021) | L18: Punj Lloyd Limited (2008-2019), Bharat Heavy Electricals Limited (2002-2007), Honda Motorcycle & Scooter India Pvt. Ltd. (2002 – 2002) | M18: Convergence | R18: 43719 | S18: 6 | T18: 5 | U18: - | Y18: 105 | Z18: 102 | AA18: 110 | AB18: Medium | AC18: High | AD18: No | AE18: - | AH18: 78 | AI18: 67 | AJ18: 91 | AK18: - | AL18: -
A19: 35001670 | B19: Sayantani Mitra | C19: Assistant Vice President - Business Development & Market Intelligence | D19: Sterlite Electric | E19: M3 | F19: Bhardwaj, Ankit | G19: Mumbai Office | I19: 1.8 | J19: 12 | K19: CFO- SEL (2026- Present) | L19: Tenneco Clean Air India Limited (2024-2026), Azure Power India Pvt Ltd (2023-2024), Sterlite Power Transmission Ltd ( 2019-20223) | M19: Marketing | S19: 5 | T19: - | U19: - | Y19: 120 | Z19: 110 | AA19: 100 | AB19: High | AC19: High | AD19: Yes | AE19: - | AH19: 66 | AI19: 88 | AJ19: 82 | AK19: - | AL19: -
A20: 24900040 | B20: Shijo Thomas | C20: Assistant Vice President - S&OP | D20: Sterlite Electric | E20: M3 | F20: Mattoo, Surinder | G20: Gurugram Office | I20: 3.8 | J20: 14 | K20: Head - Manufacturing Operations (2026-Present), Vice President - Manufacturing Operations (2024-2026) | L20: Indoasian Legrand Group (1999-2024) | M20: Manufacturing | S20: 8 | T20: 5 | U20: 5 | Y20: 80 | Z20: 88 | AA20: 100 | AB20: Medium | AC20: High | AD20: Yes | AE20: - | AH20: 89 | AI20: 89 | AJ20: 90 | AK20: - | AL20: -
A21: 35000091 | B21: Priyank Kumar Shrivastava | C21: Chief Manager - Service Delivery | D21: Sterlite Electric | E21: M4 | F21: Dangat, Nilesh | G21: Project Site - RJ | I21: 7 | J21: 23.2 | K21: Head- Strategy & M&A (2026-Present), VP - Strategy & Finance, MD Office (2024-2026) | L21: Suminter India Organic (2023-2024), Bajaj Electricals Ltd (2019-2023), Voltas Ltd (2016-2019) | M21: Convergence | S21: 5 | T21: 5 | U21: 5 | Y21: 105 | Z21: 102 | AA21: 110 | AB21: Low | AC21: Medium | AD21: Yes | AE21: - | AH21: - | AI21: - | AJ21: - | AK21: - | AL21: -
A22: 35001162 | B22: Nitin Malhotra | C22: Chief Manager - Sales & Business Development (Power Cables) | D22: Sterlite Electric | E22: M4A | F22: Kapoor, Lokesh | G22: Gurugram Office | I22: 0 | J22: 19.7 | K22: Chief Business Officer - Overhead & MSI (2021-Present) , Vice President Projects (2019-2021) | L22: Punj Lloyd Limited (2008-2019), Bharat Heavy Electricals Limited (2002-2007), Honda Motorcycle & Scooter India Pvt. Ltd. (2002 – 2002) | M22: Sales | S22: 5 | T22: 4 | U22: - | Y22: 120 | Z22: 110 | AA22: 100 | AB22: Medium | AC22: Medium | AD22: No | AE22: - | AH22: 82 | AI22: 90 | AJ22: 89 | AK22: - | AL22: -
A23: 35001066 | B23: Sunil Kumar Choubey | C23: Assistant Vice President - Projects Execution | D23: Sterlite Electric | E23: M3 | F23: Mattoo, Surinder | G23: Vadodara Plant – GJ | I23: 2.2 | J23: 29.5 | K23: CFO- SEL (2026- Present) | L23: Tenneco Clean Air India Limited (2024-2026), Azure Power India Pvt Ltd (2023-2024), Sterlite Power Transmission Ltd ( 2019-20223) | M23: Projects Execution | S23: 8 | T23: 8 | U23: 5 | Y23: 90 | Z23: 95 | AA23: 99 | AB23: High | AC23: High | AD23: Yes | AE23: - | AH23: 78 | AI23: 67 | AJ23: 91 | AK23: 94 | AL23: -
A24: 35001628 | B24: Yogish Vijay Sarang | C24: Sales Director | D24: Sterlite Electric | E24: M2 | F24: Bhardwaj, Ankit | G24: Mumbai Office | I24: 1.8 | J24: 12 | K24: Head - Manufacturing Operations (2026-Present), Vice President - Manufacturing Operations (2024-2026) | L24: Indoasian Legrand Group (1999-2024) | M24: Sales | R24: 43719 | S24: 5 | T24: 5 | U24: - | Y24: 95 | Z24: 98 | AA24: 100 | AB24: High | AC24: High | AD24: Yes | AE24: 3.67 | AH24: 66 | AI24: 88 | AJ24: 82 | AK24: - | AL24: -
A25: 35001667 | B25: Meenakshi Thusu | C25: Chief Manager - Production Planning & Control | D25: Sterlite Electric | E25: M4 | F25: Bhati, Himanshu | G25: Haridwar Plant - UKH | I25: 3.8 | J25: 14 | K25: Head- Strategy & M&A (2026-Present), VP - Strategy & Finance, MD Office (2024-2026) | L25: Suminter India Organic (2023-2024), Bajaj Electricals Ltd (2019-2023), Voltas Ltd (2016-2019) | M25: Manufacturing | S25: 8 | T25: - | U25: - | Y25: 80 | Z25: 88 | AA25: 100 | AB25: Medium | AC25: High | AD25: Yes | AE25: - | AH25: 89 | AI25: 89 | AJ25: 90 | AK25: - | AL25: -
A26: 35001218 | B26: Kiran Anant Patil | C26: Chief Manager - Operations | D26: Sterlite Electric | E26: M4 | F26: Choubey, Sunil Kumar | G26: Vadodara Plant – GJ | I26: 7 | J26: 23.2 | K26: Chief Business Officer - Overhead & MSI (2021-Present) , Vice President Projects (2019-2021) | L26: Punj Lloyd Limited (2008-2019), Bharat Heavy Electricals Limited (2002-2007), Honda Motorcycle & Scooter India Pvt. Ltd. (2002 – 2002) | M26: Manufacturing | S26: 5 | T26: 5 | U26: - | Y26: 105 | Z26: 102 | AA26: 110 | AB26: Medium | AC26: Medium | AD26: Yes | AE26: - | AH26: - | AI26: - | AJ26: - | AK26: - | AL26: -
A27: 35001383 | B27: Sisir Kumar Parida | C27: Chief Manager - Projects | D27: Sterlite Electric | E27: M4 | F27: Sharma, Satyendra Kumar | G27: Project Site - OR | I27: 0 | J27: 19.7 | K27: CFO- SEL (2026- Present) | L27: Tenneco Clean Air India Limited (2024-2026), Azure Power India Pvt Ltd (2023-2024), Sterlite Power Transmission Ltd ( 2019-20223) | M27: Projects Execution | R27: 43565 | S27: 1 | T27: 2 | U27: - | Y27: 120 | Z27: 110 | AA27: 100 | AB27: High | AC27: High | AD27: Yes | AE27: - | AH27: - | AI27: - | AJ27: - | AK27: - | AL27: -
A28: 24902509 | B28: Pawan Jain | C28: Chief Manager - Quality | D28: Sterlite Electric | E28: M4A | F28: Gulati, Rajesh Kumar | G28: Haridwar Plant - UKH | I28: 2.2 | J28: 29.5 | K28: Head - Manufacturing Operations (2026-Present), Vice President - Manufacturing Operations (2024-2026) | L28: Indoasian Legrand Group (1999-2024) | M28: QHSE | R28: 44119 | S28: 5 | T28: 5 | U28: 5 | Y28: 90 | Z28: 95 | AA28: 99 | AB28: Medium | AC28: Medium | AD28: Yes | AE28: - | AH28: - | AI28: - | AJ28: - | AK28: - | AL28: -
A29: 35000704 | B29: Manas Kumar | C29: Chief Manager - Quality, Health, Environment & Safety | D29: Sterlite Electric | E29: M4A | F29: Singh, Akhilesh | G29: Gurugram Office | I29: 1.8 | J29: 12 | K29: Head- Strategy & M&A (2026-Present), VP - Strategy & Finance, MD Office (2024-2026) | L29: Suminter India Organic (2023-2024), Bajaj Electricals Ltd (2019-2023), Voltas Ltd (2016-2019) | M29: QHSE | S29: 5 | T29: 5 | U29: 5 | Y29: 95 | Z29: 98 | AA29: 100 | AB29: Medium | AC29: High | AD29: No | AE29: - | AH29: 78 | AI29: 79 | AJ29: 80 | AK29: - | AL29: -
A30: 35001931 | B30: Balaji Rao Thorhath | C30: Chief Manager - Sales & Business Development (Power Cables) | D30: Sterlite Electric | E30: M4 | F30: Kapoor, Lokesh | G30: Project Site - KA | I30: 3.8 | J30: 14 | K30: Chief Business Officer - Overhead & MSI (2021-Present) , Vice President Projects (2019-2021) | L30: Punj Lloyd Limited (2008-2019), Bharat Heavy Electricals Limited (2002-2007), Honda Motorcycle & Scooter India Pvt. Ltd. (2002 – 2002) | M30: Sales | S30: 5 | T30: - | U30: - | Y30: 80 | Z30: 88 | AA30: 100 | AB30: Low | AC30: Medium | AD30: No | AE30: - | AH30: 89 | AI30: 90 | AJ30: 88 | AK30: - | AL30: -
A31: 35000422 | B31: Ankit Bhardwaj | C31: Chief Business Officer - Overhead & MSI | D31: Sterlite Electric | E31: M1 | F31: Trefois, Frederic | G31: Gurugram Office | I31: 7 | J31: 23.2 | K31: CFO- SEL (2026- Present) | L31: Tenneco Clean Air India Limited (2024-2026), Azure Power India Pvt Ltd (2023-2024), Sterlite Power Transmission Ltd ( 2019-20223) | M31: Projects Execution | S31: 5 | T31: 7 | U31: 8 | Y31: 105 | Z31: 102 | AA31: 110 | AB31: Medium | AC31: High | AD31: No | AE31: - | AH31: 82 | AI31: 90 | AJ31: 89 | AK31: - | AL31: 83
A32: 35001199 | B32: Rabi Prasad | C32: Chief Manager - Health, Environment & Safety | D32: Sterlite Electric | E32: M4 | F32: GOUDA, VISHNU NATH | G32: Rakholi Plant - DNH | I32: 0 | J32: 19.7 | K32: Head - Manufacturing Operations (2026-Present), Vice President - Manufacturing Operations (2024-2026) | L32: Indoasian Legrand Group (1999-2024) | M32: QHSE | S32: 2 | T32: 4 | U32: - | Y32: 120 | Z32: - | AA32: - | AB32: High | AC32: High | AD32: Yes | AE32: - | AH32: 78 | AI32: 67 | AJ32: 91 | AK32: - | AL32: -
A33: 24903254 | B33: Rajesh Kumar Gulati | C33: Assistant Vice President - Quality | D33: Sterlite Electric | E33: M3A | F33: Biswas, Dhritiman | G33: Haridwar Plant - UKH | I33: 2.2 | J33: 29.5 | K33: Head- Strategy & M&A (2026-Present), VP - Strategy & Finance, MD Office (2024-2026) | L33: Suminter India Organic (2023-2024), Bajaj Electricals Ltd (2019-2023), Voltas Ltd (2016-2019) | M33: QHSE | S33: 5 | T33: 5 | U33: 5 | Y33: - | Z33: - | AA33: - | AB33: High | AC33: High | AD33: Yes | AE33: - | AH33: 66 | AI33: 88 | AJ33: 82 | AK33: - | AL33: -
A34: 24903716 | B34: Prasad S | C34: Chief Manager - Plant NPD | D34: Sterlite Electric | E34: M4A | F34: Mattoo, Surinder | G34: Piparia Plant - DNH | I34: 1.8 | J34: 12 | K34: Chief Business Officer - Overhead & MSI (2021-Present) , Vice President Projects (2019-2021) | L34: Punj Lloyd Limited (2008-2019), Bharat Heavy Electricals Limited (2002-2007), Honda Motorcycle & Scooter India Pvt. Ltd. (2002 – 2002) | M34: Plant NPD | S34: 8 | T34: 8 | U34: 8 | Y34: 95 | Z34: - | AA34: 100 | AB34: High | AC34: High | AD34: Yes | AE34: - | AH34: 89 | AI34: 89 | AJ34: 90 | AK34: - | AL34: -
A35: 35000240 | B35: Mohd Wasiqur Rahman | C35: Chief Manager - Service Delivery | D35: Sterlite Electric | E35: M4 | F35: Dangat, Nilesh | G35: Gurugram Office | I35: 3.8 | J35: 14 | K35: CFO- SEL (2026- Present) | L35: Tenneco Clean Air India Limited (2024-2026), Azure Power India Pvt Ltd (2023-2024), Sterlite Power Transmission Ltd ( 2019-20223) | M35: Convergence | S35: 6 | T35: - | U35: - | Y35: 80 | Z35: 88 | AA35: 100 | AB35: Low | AC35: High | AD35: Yes | AE35: - | AH35: - | AI35: - | AJ35: - | AK35: - | AL35: -
A36: 24900448 | B36: Jignesh U Panchal | C36: Chief Manager - Maintenance | D36: Sterlite Electric | E36: M4A | F36: Chowdhury, Ratul | G36: Piparia Plant - DNH | I36: 7 | J36: 23.2 | K36: Head - Manufacturing Operations (2026-Present), Vice President - Manufacturing Operations (2024-2026) | L36: Indoasian Legrand Group (1999-2024) | M36: Manufacturing | S36: 5 | T36: 5 | U36: 5 | Y36: 105 | Z36: 102 | AA36: 110 | AB36: Medium | AC36: High | AD36: No | AE36: - | AH36: 82 | AI36: 90 | AJ36: 89 | AK36: - | AL36: -
A37: 35001325 | B37: VISHNU NATH GOUDA | C37: Assistant Vice President- Products Safety | D37: Sterlite Electric | E37: M3 | F37: Mattoo, Surinder | G37: Rakholi Plant - DNH | I37: 0 | J37: 19.7 | K37: Head- Strategy & M&A (2026-Present), VP - Strategy & Finance, MD Office (2024-2026) | L37: Suminter India Organic (2023-2024), Bajaj Electricals Ltd (2019-2023), Voltas Ltd (2016-2019) | M37: QHSE | S37: 2 | T37: 4 | U37: - | Y37: 120 | Z37: 110 | AA37: 100 | AB37: Medium | AC37: Low | AD37: Yes | AE37: - | AH37: 78 | AI37: 67 | AJ37: 91 | AK37: - | AL37: -
A38: 35001160 | B38: Vibhor Gupta | C38: Sales Director | D38: Sterlite Electric | E38: M3A | F38: Biswas, Dhritiman | G38: Gurugram Office | I38: 2.2 | J38: 29.5 | K38: Chief Business Officer - Overhead & MSI (2021-Present) , Vice President Projects (2019-2021) | L38: Punj Lloyd Limited (2008-2019), Bharat Heavy Electricals Limited (2002-2007), Honda Motorcycle & Scooter India Pvt. Ltd. (2002 – 2002) | M38: Sales | S38: 5 | T38: 8 | U38: - | Y38: 80 | Z38: 88 | AA38: 100 | AB38: High | AC38: High | AD38: Yes | AE38: - | AH38: 66 | AI38: 88 | AJ38: 82 | AK38: - | AL38: -
A39: 24902186 | B39: Sankarganesh Kesavan | C39: Chief Manager - Projects | D39: Sterlite Electric | E39: M4 | F39: Bhardwaj, Ankit | G39: Project Site - TN | I39: 1.8 | J39: 12 | K39: CFO- SEL (2026- Present) | L39: Tenneco Clean Air India Limited (2024-2026), Azure Power India Pvt Ltd (2023-2024), Sterlite Power Transmission Ltd ( 2019-20223) | M39: Projects Execution | S39: 5 | T39: 3 | U39: 2 | Y39: 105 | Z39: - | AA39: - | AB39: Medium | AC39: Medium | AD39: Yes | AE39: - | AH39: 89 | AI39: 89 | AJ39: 90 | AK39: - | AL39: -
A40: 35000935 | B40: Chaitan Goyal | C40: Head Strategic Sourcing | D40: Sterlite Electric | E40: M3A | F40: Trefois, Frederic | G40: Gurugram Office | I40: 3.8 | J40: 14 | K40: Head - Manufacturing Operations (2026-Present), Vice President - Manufacturing Operations (2024-2026) | L40: Indoasian Legrand Group (1999-2024) | M40: Supply Chain Management | S40: 6 | T40: 9 | U40: 8 | Y40: 120 | Z40: 110 | AA40: 100 | AB40: High | AC40: High | AD40: Yes | AE40: - | AH40: - | AI40: - | AJ40: - | AK40: - | AL40: -
...

Sheet LOGO
A1: Company name | B1: Logo
A2: Resonia | B2: #VALUE!
A3: Serentica | B3: #VALUE!
A4: Sterlite | B4: #VALUE!
A5: Sterlite Electric | B5: #VALUE!

Sheet Future Readiness
A1: EmpID | B1: Timeline | C1: Role
A2: 35000971 | B2: Ready in 2-3 years | C2: Head - Indirect Tax (Group)
A3: 24902762 | B3: Ready now | C3: Chief Manager 1
A4: 35001624 | B4: Ready in 1-2 years | C4: Chief manager -M4 A
A5: 24903254 | B5: Ready in 2-3 years | C5: NPD
A6: 35001535 | B6: Ready in 1-2 years | C6: Head - Strategic Sourcing
A7: 24900980 | B7: Ready in 2-3 years | C7: Production Head
A8: 35001179 | B8: Ready now | C8: Head- Markets and Ops
A9: 24903846 | B9: Ready now | C9: BD Head and DCI Business India
A10: 35000592 | B10: Ready in 2-3 years | C10: Lead Regulatory
A11: 35000954 | B11: Ready now | C11: OPGW, HTLS, Conductors & Infra EPC Projects , Circle leaded
A12: 35000240 | B12: Ready now | C12: Circle Manager
A13: 35001689 | B13: Ready now | C13: HVDC PMT
... A157: 24901000 | B157: Ready now | C157: M&A and Equity Fund Raise

Sheet Competency Profile
A1: EmpID | B1: Type | C1: Item
A2: 24900040 | B2: Core Strength | C2: Good at SOP.
A3: 24900040 | B3: Development Area | C3: Need to further develop on Succession Planning.
A4: 24900041 | B4: Core Strength | C4: OPGW Quality Expert
A5: 24900041 | B5: Development Area | C5: Need to increase his knowledge in Conductor and take more ownership
A6: 24900062 | B6: Core Strength | C6: Adaptability Flexibility Collaboration Teamwork Accountability Integrity
A7: 24900062 | B7: Development Area | C7: 1) Commucnation 2) Substation techncial and costing
A8: 24900095 | B8: Core Strength | C8: Susmita is diligent and thorough about her work. She wears our values on her chest with pride.
A9: 24900095 | B9: Development Area | C9: 1. Communication - written and oral2. Delegation of work3. A bit of team management and grooming
A10: 24900122 | B10: Core Strength | C10: Strong connects and understanding on regulatory and regulatory authorities.
A11: 24900122 | B11: Development Area | C11: Needs to work on team management and bring system approach to regulatory.
A12: 24900167 | B12: Core Strength | C12: Good experience as a co-ordinator between Sales and Production, Sharing daily MIS updates on FG stock and sales nos.,Consolidation of Sales nos for overall OH business.
A13: 24900167 | B13: Development Area | C13: Need to expand roles possibly as overall Planner.
... A350: 35000745 | B350: Core Strength | C350: 1) Communication Clarity2) Leadership skills3) Goal Oriented Focus
A351: 35000745 | B351: Core Strength
A352: 35000745 | B352: Core Strength
A353: 35000745 | B353: Development Area | C353: 1) Process Improvement2) Regular Review Sessions
A354: 35000747 | B354: Core Strength | C354: Good relationship Management across the sector and informative market intelligence
A355: 35000747 | B355: Development Area | C355: May strengthen public relations with other stakeholders in the sector
A356: 35000749 | B356: Core Strength | C356: Extremely hard working, ability to be focused, patient on deliverables, and an excellent team member
A357: 35000749 | B357: Development Area | C357: To be more in the limelight and take initiative (has definitely improved from the last year)
A358: 35000795 | B358: Core Strength | C358: Land policies and land act knowledge is good.
A359: 35000795 | B359: Development Area | C359: He is handling important work portfolio but lacks initiatives and energy. Self motivation needs to be boosted.
A360: 35000803 | B360: Core Strength | C360: Highly motivated with the ability to take initiative Dedicated, disciplined, and committedGood communication skills with the ability to influence, negotiate
A361: 35000803 | B361: Development Area | C361: - Building deeper knowledge and hands-on experience in substation systems- Focus on developing stronger leadership presence through confident communication, strategic thinking, and polished professional interactions.
A362: 35000812 | B362: Core Strength | C362: Good Knowledge
A363: 35000812 | B363: Development Area | C363: Team Development , leadership skills
A364: 35000838 | B364: Core Strength | C364: Delivering on tough/non-glamorous/boring yet high-impact assignments; People management; Stakeholder management
... A831: 35002397 | B831: Development Area | C831: Needs to build her business Acumen

Sheet Actionable
A1: EmpID | C1: Type | D1: Action | E1: Status | F1: Remark | I1: Action Taken | J1: Action Proposed
A2: 35001397 | B2: =VLOOKUP(A2,Profile!A:A,1,0) -> #N/A | C2: Action Taken | D2: Strategy & Business Planning- More focus on Con, MSI | E2: To be Initiated | F2: Prashant to check with Pratik
A3: 35001397 | B3: =VLOOKUP(A3,Profile!A:A,1,0) -> #N/A | C3: Action Taken | D3: Coaching/Mentoring- Mentorship through Rakesh to young leaders - include this aspect as part of high potential program | E3: To be Initiated | F3: Will be part of High Pot program
A4: 35002222 | B4: =VLOOKUP(A4,Profile!A:A,1,0) -> #N/A | C4: Action Taken | D4: Role Alignment- Needs alignment on his role | E4: To be Initiated | F4: Prashant to check with Rohit
A5: 35001397 | B5: =VLOOKUP(A5,Profile!A:A,1,0) -> #N/A | C5: Action Taken | D5: Strategic Project Exposure- Play a key role in IPO - lead marketing, go on road shows with Frederic and Manish - needs to be communicated to Rakesh | E5: In Progress
A6: 35001880 | B6: =VLOOKUP(A6,Profile!A:A,1,0) -> #N/A | C6: Action Taken | D6: Feedback- Seek feedback from Arun and Prashant Sinha on the role he played in the Sankalp transformation | E6: In Progress
A7: 35001397 | B7: =VLOOKUP(A7,Profile!A:A,1,0) -> #N/A | C7: Action Taken | D7: Feedback- Emotional regulation | E7: Closed | F7: Feedback session completed with Pratik
A8: 35001397 | B8: =VLOOKUP(A8,Profile!A:A,1,0) -> #N/A | C8: Action Taken | D8: Role Change- Could be moved to live roles in business, well thought of line role (Sale, mfg, CTO?, +1) Opportunities eg accessories etc could be good to explore. CXO role in SEL . More like Lunmiker kind of opportunities Ruhie/Pratik to discuss | E8: Closed | F8: Conversation Completed & announced by Fredrick - will move to SEL (role movement in progress)
A9: 35001397 | B9: =VLOOKUP(A9,Profile!A:A,1,0) -> #N/A | C9: Action Taken | D9: Career Development Conversation- Career discussion with Pratik | E9: Closed | F9: Discussion done with Pratik, Ruhie & Rakesh
A10: 35000742 | B10: =VLOOKUP(A10,Profile!A:A,1,0) -> #N/A | C10: Action Taken | D10: Role Change- AOD: Ability to influence, ability to influence (cannot just convey strategy), should have his own point of view Career conversation in January with Pratik. Explore roles - move to a line function by June Potential roles: Roles: 1. Project Assurance in Resonia, issue is with the last mile delivery, might work if Prashant Sinha, we could add more (would this be a step up for him?) 2. CCO HVDC - Program Manager 3. Claims & contracts? 4. Cost Excellence Serentica? Maybe No Find a role where he does not need high amount of influencing | E10: Closed | F10: Discussion Completed with Pratik & Ruhie concluded - (Continue in current role for now)
A11: 35001880 | B11: =VLOOKUP(A11,Profile!A:A,1,0) -> #N/A | C11: Action Taken | D11: Capability Building- Rohit & Rakesh to work on M&A frameworking (Peer learning) | E11: Closed | F11: Not going ahead
A12: 35001880 | B12: =VLOOKUP(A12,Profile!A:A,1,0) -> #N/A | C12: Action Taken | D12: Career Development Conversation- He builds Internal SME Team. Possible areas for him Manufacturing focused projects? Ease the 33 kV load (Akshay), reverse engineering projects in Serentica Program manager for HVDC Strategy? (A MT can be assigned to him)- discussion with Pratik | E12: Closed | F12: discussion with Pratik done
A13: 35001141 | B13: =VLOOKUP(A13,Profile!A:A,1,0) -> 35001141 | C13: Action Taken | D13: No Immediate Action- No action | E13: NA
A14: 35001312 | B14: =VLOOKUP(A14,Profile!A:A,1,0) -> 35001312 | C14: Action Taken | D14: Feedback- Nudge Buddy: Will need constant feedback on the people management front; He needs to develop an appreciation of people skilled in ppl mgmt. | E14: In Progress | F14: Coach to be identified
A15: 35001312 | B15: =VLOOKUP(A15,Profile!A:A,1,0) -> 35001312 | C15: Action Taken | D15: Feedback- Needs to be given some assurance that there is some scope for failure to reduce perf anxiety | E15: In Progress | F15: Coach to be identified
A16: 35000365 | B16: =VLOOKUP(A16,Profile!A:A,1,0) -> 35000365 | C16: Action Taken | D16: Coaching/Mentoring- Continue to be coached | E16: In Progress | F16: Continue coaching for next 6 months
A17: 35001293 | B17: =VLOOKUP(A17,Profile!A:A,1,0) -> 35001293 | C17: Action Taken | D17: Role Enhancement- To support in oscillations for Serentica | E17: To be Initiated
A18: 35001293 | B18: =VLOOKUP(A18,Profile!A:A,1,0) -> 35001293 | C18: Action Taken | D18: Coaching/Mentoring- Get Tushar to peer mentor him, to inform him how O&M impacts IRR | E18: To be Initiated
A19: 35001293 | B19: =VLOOKUP(A19,Profile!A:A,1,0) -> 35001293 | C19: Action Taken | D19: Talent To be Assessed- Start assessing him on technical ability, rather than commercial ability (speaks to brand promise) | E19: In Progress
A20: 24900122 | B20: =VLOOKUP(A20,Profile!A:A,1,0) -> 24900122 | C20: Action Taken | D20: Successor Identification- Successor to be groomed | E20: To be Initiated
A21: 35000376 | B21: =VLOOKUP(A21,Profile!A:A,1,0) -> 35000376 | C21: Action Taken | D21: Capability Building- Place him in a course where he can network - wit IAS.IPS (MDI, Adm staff college Hyderabad)
A22: 35000376 | B22: =VLOOKUP(A22,Profile!A:A,1,0) -> 35000376 | C22: Action Taken | D22: Capability Building- Pratik can take him to events - All MH IAS/IPS
A23: 35001189 | B23: =VLOOKUP(A23,Profile!A:A,1,0) -> 35001189 | C23: Action Taken | D23: Capability Building- Put him in a COO program and groom him for next level | E23: To be Initiated
A24: 35001189 | B24: =VLOOKUP(A24,Profile!A:A,1,0) -> 35001189 | C24: Action Taken | D24: Capability Building- Stakeholder management to be enhanced | E24: In Progress | F24: Coach to be identified
A25: 24902503 | B25: =VLOOKUP(A25,Profile!A:A,1,0) -> 24902503 | C25: Action Taken | D25: Successor Identification- Identify and develop his successor , move him to PD | E25: To be Initiated
A26: 24902503 | B26: =VLOOKUP(A26,Profile!A:A,1,0) -> 24902503 | C26: Action Taken | D26: Capability Building- His stakeholder mgmt. skills needs to be enhanced | E26: In Progress | F26: Coach to be identified
A27: 24903214 | B27: =VLOOKUP(A27,Profile!A:A,1,0) -> 24903214 | C27: Action Taken | D27: Talent To be Assessed- Reassess after a while | E27: In Progress
A28: 35000686 | B28: =VLOOKUP(A28,Profile!A:A,1,0) -> 35000686 | C28: Action Taken | D28: Capability Building- Team management - seems demotivated | E28: In Progress
A29: 35000686 | B29: =VLOOKUP(A29,Profile!A:A,1,0) -> 35000686 | C29: Action Taken | D29: Capability Building- Connect in market | E29: In Progress
A30: 35000896 | B30: =VLOOKUP(A30,Profile!A:A,1,0) -> #N/A | C30: Action Taken | D30: Feedback- Delegation of work (Feedback through CEO track program) | E30: Closed | F30: Closed no action
A31: 35000896 | B31: =VLOOKUP(A31,Profile!A:A,1,0) -> #N/A | C31: Action Taken | D31: Capability Building- Need to develop a training program for his n-1 (Mattoo: Strategy; Dhritiman: Execution) | E31: Closed | F31: Closed no action
A32: 35000422 | B32: =VLOOKUP(A32,Profile!A:A,1,0) -> 35000422 | C32: Action Taken | D32: Successor Identification- Build the team under him | E32: Closed | F32: new role under consideration
A33: 35000422 | B33: =VLOOKUP(A33,Profile!A:A,1,0) -> 35000422 | C33: Action Taken | D33: Strategy & Business Planning- MD office to support Ankit B in business plan for the next year | E33: Closed | F33: new role under consideration
A34: 35000286 | B34: =VLOOKUP(A34,Profile!A:A,1,0) -> 35000286 | C34: Action Taken | D34: Strategy & Business Planning- Need for a strategic review of the Convergence business and firm up the plan on next steps ( target date September 2026). Need to create an opportunity to get investment, due to the push in data centre demands. We should focus on getting in some investments ideally by Sep 2026 (spin off) | E34: Closed | F34: closed - discussion with CEO initiated
A35: 35000286 | B35: =VLOOKUP(A35,Profile!A:A,1,0) -> 35000286 | C35: Action Taken | D35: Revision in Box Rating- Relook at Box rating - should be Box 6, bump up performance | E35: To be Initiated | F35: will be taken up in TR calibration for FY26
A36: 35000286 | B36: =VLOOKUP(A36,Profile!A:A,1,0) -> 35000286 | C36: Action Taken | D36: Capability Building- Identify a course for Strategy week long (with premiere institutes) | E36: To be Initiated | F36: to be identified by OTD
A37: 35000286 | B37: =VLOOKUP(A37,Profile!A:A,1,0) -> 35000286 | C37: Action Taken | D37: Capability Building- Identify a course on corporate finance (Raising equity, valution models - market caps etc., | E37: To be Initiated | F37: Post the above program to be identified
A38: 35001594 | B38: =VLOOKUP(A38,Profile!A:A,1,0) -> 35001594 | C38: Action Taken | D38: Org/team structure- Addition of resources in the team to manage work life balance due to exits | E38: Hold | F38: hold -positions on hold, appropriate call to be taken
A39: 35001594 | B39: =VLOOKUP(A39,Profile!A:A,1,0) -> 35001594 | C39: Action Taken | D39: Coaching/Mentoring- Mentoring from Sumil | E39: Closed | F39: closed
A40: 35001918 | B40: =VLOOKUP(A40,Profile!A:A,1,0) -> #N/A | C40: Action Taken | D40: Coaching/Mentoring- Coaching from Federic would help | E40: Closed | F40: closed
...

Sheet Potential Successors
A1: EmpID | B1: Successor Name | C1: Readiness
A2: 35001888 | B2: Anandhakrishnan K M | C2: Ready in 1 to 2 years
A3: 24901052 | B3: Viren Kumar Patel | C3: Ready Now
A4: 35001830 | B4: Atul Sharma | C4: Ready Now
A5: 35001526 | B5: Ratneswar Mukherjee | C5: Ready Now
A6: 35001467 | B6: Deependra Singh | C6: Ready Now
A7: 35001214 | B7: Anshul Tripathi | C7: Ready Now
A8: 35001146 | B8: Anmol Maheshwari | C8: Ready in 1 to 2 years
A9: 35001578 | B9: Anisha Chopra | C9: Ready Now
A10: 35001186 | B10: Alisha Singh | C10: Ready in 2 to 3 years
A11: 35001525 | B11: Smruti Sephali Gouda | C11: Ready in 2 to 3 years
A12: 35000426 | B12: Shantanu Bhardwaj | C12: Ready in 2 to 3 years
A13: 35001691 | B13: Nabyendu Mukherjee | C13: Ready in 1 to 2 years
... A160: 35000681 | B160: Shashi Bhadoola | C160: Ready in 2 to 3 years
A161: admin01 | B161: Urvashi Jindal | C161: Ready Now
A162: admin01 | B162: Urvashi Jindal | C162: Ready Now
A163: 35001132 | B163: Amit Kumar Singh | C163: Ready in 2 to 3 years
A164: 35001040 | B164: Akash Srivastava | C164: Ready in 1 to 2 years
A165: 35001040 | B165: Akash Srivastava | C165: Ready in 1 to 2 years
A166: 35001032 | B166: Shivani Srivastava | C166: Ready in 1 to 2 years
A167: 35001028 | B167: Somraj Kar | C167: Ready Now
A168: 35001028 | B168: Somraj Kar | C168: Ready Now
A169: 24902092 | B169: Deepak Rathore | C169: Ready in 3+ years
A170: 24902066 | B170: Ashok Kumar Chauhan | C170: Ready in 1 to 2 years
A171: 24902272 | B171: K Vijaya Kumar | C171: Ready Now
A172: 35000423 | B172: Abhishek Garg | C172: Ready in 2 to 3 years
A173: 35001405 | B173: Pragya Agrawal | C173: Ready in 2 to 3 years
A174: 35000636 | B174: Rohit Ishwarrao Muppidwar | C174: Ready in 1 to 2 years
... A203: 35000393 | B203: Rajesh Mathankar | C203: Ready in 2 to 3 years
